Sent message: ID=0xc7, Data=[170, 187, 204]
Sent message: ID=0xc8, Data=[170, 187, 204]
Exception in thread Thread-1 (receive_can_messages):
Traceback (most recent call last):
  File "d:\OneDrive - LTTS\Desktop\Can_basic\EdgeSolution\EdgeSolution\modules\SampleModule\new1.py", line 19, in receive_can_messages
    message = bus.recv(timeout=1)
  File "C:\Users\40020507\AppData\Local\Packages\PythonSoftwareFoundation.Python.3.10_qbz5n2kfra8p0\LocalCache\local-packages\Python310\site-packages\can\bus.py", line 98, in recv
    msg, already_filtered = self._recv_internal(timeout=time_left)
  File "C:\Users\40020507\AppData\Local\Packages\PythonSoftwareFoundation.Python.3.10_qbz5n2kfra8p0\LocalCache\local-packages\Python310\site-packages\can\interfaces\virtual.py", line 95, in _recv_internal
    self._check_if_open()
  File "C:\Users\40020507\AppData\Local\Packages\PythonSoftwareFoundation.Python.3.10_qbz5n2kfra8p0\LocalCache\local-packages\Python310\site-packages\can\interfaces\virtual.py", line 90, in _check_if_open
    raise CanOperationError("Cannot operate on a closed bus")
can.exceptions.CanOperationError: Cannot operate on a closed bus

During handling of the above exception, another exception occurred:

Traceback (most recent call last):
  File "C:\Program Files\WindowsApps\PythonSoftwareFoundation.Python.3.10_3.10.3056.0_x64__qbz5n2kfra8p0\lib\threading.py", line 1016, in _bootstrap_inner
    self.run()
  File "C:\Program Files\WindowsApps\PythonSoftwareFoundation.Python.3.10_3.10.3056.0_x64__qbz5n2kfra8p0\lib\threading.py", line 953, in run
    self._target(*self._args, **self._kwargs)
  File "d:\OneDrive - LTTS\Desktop\Can_basic\EdgeSolution\EdgeSolution\modules\SampleModule\new1.py", line 23, in receive_can_messages
    print(f"Exception in thread{Thread.current_thread().name}:{e}")
AttributeError: type object 'Thread' has no attribute 'current_thread'
