Traceback (most recent call last): File "C:\Users\40020507\AppData\Local\Packages\PythonSoftwareFoundation.Python.3.10_qbz5n2kfra8p0\LocalCache\local-packages\Python310\site-packages\azure\iot\device\iothub\abstract_clients.py", line 743, in create_from_edge_environment connection_string = os.environ["EdgeHubConnectionString"] File "C:\Program Files\WindowsApps\PythonSoftwareFoundation.Python.3.10_3.10.3056.0_x64__qbz5n2kfra8p0\lib\os.py", line 680, in __getitem__ raise KeyError(key) from None KeyError: 'EdgeHubConnectionString' The above exception was the direct cause of the following exception: Traceback (most recent call last): File "d:\loggingModule\src\logagent\utils\test.py", line 5, in <module> obj1.connect() File "d:\loggingModule\src\logagent\utils\azurecomm.py", line 29, in connect self.client = IoTHubModuleClient.create_from_edge_environment() File "C:\Users\40020507\AppData\Local\Packages\PythonSoftwareFoundation.Python.3.10_qbz5n2kfra8p0\LocalCache\local-packages\Python310\site-packages\azure\iot\device\patch_documentation.py", line 228, in create_from_edge_environment return super(IoTHubModuleClient, cls).create_from_edge_environment(**kwargs) File "C:\Users\40020507\AppData\Local\Packages\PythonSoftwareFoundation.Python.3.10_qbz5n2kfra8p0\LocalCache\local-packages\Python310\site-packages\azure\iot\device\iothub\abstract_clients.py", line 748, in create_from_edge_environment raise new_err OSError: IoT Edge environment not configured correctly
